Workbook

Sheet Executive_Summary
A1: 3×3 Hollow-Rod Array — Updated Theoretical + FEA Design Screening
A4: PRIMARY SELECTION | D4: DURABILITY CHALLENGER | G4: SHORT / STIFF CONTROL | J4: FORMAL FAILURE
A5: ="Run 6"&CHAR(10)&"Score / metric: "&TEXT(Combined_Ranking!J9,"0.000")&CHAR(10)&"t = 1.75 mm; H = 5.25 mm Best balanced / sensitivity design" -> Run 6 Score / metric: 0.962 t = 1.75 mm; H = 5.25 mm Best balanced / sensitivity design | D5: ="Run 5"&CHAR(10)&"Score / metric: "&TEXT(Combined_Ranking!L8,"0.000")&CHAR(10)&"t = 1.75 mm; H = 3.50 mm Highest durability-first score" -> Run 5 Score / metric: 0.954 t = 1.75 mm; H = 3.50 mm Highest durability-first score | G5: ="Run 4"&CHAR(10)&"Score / metric: "&TEXT(FEA_Raw!N7,"0.000")&CHAR(10)&"0.52259 mJ Highest solved strain energy" -> Run 4 Score / metric: 0.523 0.52259 mJ Highest solved strain energy | J5: Run 7 Failed the required 1.25 mm nonlinear solve No extrapolation permitted
A10: Final engineering verdict
A11: Run 6 is the most defensible main geometry: its 1.75 mm wall preserves the preferred 25% hollow-area ratio, while the 5.25 mm height lowers the force requirement and produces the strongest solved strain localization. Run 5 is the correct companion prototype because its medium height gives the best durability-oriented balance. Run 4 should be retained as a short/stiff activation and durability control, and Run 9 as a tall near-solid control. Run 7 remains a formal failure at the required 1.25 mm indentation.
A17: Priority | B17: Run | C17: Geometry | D17: |Fz| (N) | E17: Eq. strain max | F17: Energy (mJ) | G17: Lateral ratio | H17: Balanced score | I17: Why it is retained | J17: Key mechanism findings
A18: ="1 — Primary" -> 1 — Primary | B18: =Combined_Ranking!A9 -> 6 | C18: ="t="&TEXT(Combined_Ranking!B9,"0.000")&" mm; H="&TEXT(Combined_Ranking!C9,"0.000")&" mm" -> t=1.750 mm; H=5.250 mm | D18: =Derived_Metrics!E9 -> 0.38815 | E18: =Derived_Metrics!T9 -> 0.41045 | F18: =Derived_Metrics!U9 -> 0.24758 | G18: =Derived_Metrics!H9 -> 0.256176 | H18: =Combined_Ranking!J9 -> 0.96205683 | I18: =Combined_Ranking!P9 -> Best balanced and sensitivity-oriented preferred-wall design. | J18: 1.75 mm wall is the preferred mechanism level: 25% cavity area.
A19: ="2 — Challenger" -> 2 — Challenger | B19: =Combined_Ranking!A8 -> 5 | C19: ="t="&TEXT(Combined_Ranking!B8,"0.000")&" mm; H="&TEXT(Combined_Ranking!C8,"0.000")&" mm" -> t=1.750 mm; H=3.500 mm | D19: =Derived_Metrics!E8 -> 0.52946 | E19: =Derived_Metrics!T8 -> 0.39425 | F19: =Derived_Metrics!U8 -> 0.31364 | G19: =Derived_Metrics!H8 -> 0.28035547 | H19: =Combined_Ranking!J8 -> 0.93605792 | I19: =Combined_Ranking!P8 -> Best durability-oriented preferred-wall design; fabricate alongside Run 6. | J19: 0.875 mm walls are over-hollowed at 56.25% cavity area.
A20: ="3 — Control" -> 3 — Control | B20: =Combined_Ranking!A7 -> 4 | C20: ="t="&TEXT(Combined_Ranking!B7,"0.000")&" mm; H="&TEXT(Combined_Ranking!C7,"0.000")&" mm" -> t=1.750 mm; H=1.750 mm | D20: =Derived_Metrics!E7 -> 1.1661 | E20: =Derived_Metrics!T7 -> 0.54173 | F20: =Derived_Metrics!U7 -> 0.52259 | G20: =Derived_Metrics!H7 -> 0.36111769 | H20: =Combined_Ranking!J7 -> 0.69257997 | I20: =Combined_Ranking!P7 -> Use as the durability and strong-activation control. | J20: 2.625 mm walls are near-solid at only 6.25% cavity area.
A21: ="4 — Control" -> 4 — Control | B21: =Combined_Ranking!A12 -> 9 | C21: ="t="&TEXT(Combined_Ranking!B12,"0.000")&" mm; H="&TEXT(Combined_Ranking!C12,"0.000")&" mm" -> t=2.625 mm; H=5.250 mm | D21: =Derived_Metrics!E12 -> 0.58161 | E21: =Derived_Metrics!T12 -> 0.44393 | F21: =Derived_Metrics!U12 -> 0.32715 | G21: =Derived_Metrics!H12 -> 0.2194765 | H21: =Combined_Ranking!J12 -> 0.86219468 | I21: =Combined_Ranking!P12 -> Useful to test whether the hollow mechanism adds value. | J21: H = 5.25 mm favors sensitivity; H = 3.50 mm favors durability.
A22: ="Rejected" -> Rejected | B22: =Combined_Ranking!A10 -> 7 | C22: ="t="&TEXT(Combined_Ranking!B10,"0.000")&" mm; H="&TEXT(Combined_Ranking!C10,"0.000")&" mm" -> t=2.625 mm; H=1.750 mm | D22: N/A — failed solve | E22: N/A — failed solve | F22: N/A — failed solve | G22: N/A — failed solve | H22: 0 | I22: =Combined_Ranking!P10 -> Reject from the primary design set; retain failed solution only as diagnostic evidence. | J22: Corrected Runs 1, 5, and 8 now have comparable contact/indenter conditions.
J23: Run 7 failed even with aggressive nonlinear controls.
A25: Required validation before thesis-level finalization
A26: 1 | B26: Fit the actual 70 wt% filled composite to a hyperelastic material model using UTM data.
A27: 2 | B27: Perform local mesh convergence on Runs 5 and 6; compare force, strain, energy, and lateral ratio.
A28: 3 | B28: Fabricate Runs 5 and 6 plus Runs 4 and 9 as controls; calibrate force versus emitted light.
A29: 4 | B29: Record neighboring-taxel intensity to verify that Run 6's higher localization also reduces optical/mechanical cross-talk.

Sheet Inputs_Theory
A1: 3×3 Hollow-Rod Array — Inputs, Material Model, and Screening Rules
K3: Transparent scoring thresholds
A4: Fixed geometry | D4: ANSYS Neo-Hookean material model | H4: Design levels | K4: Eq. strain zero-low | L4: 0.15 | M4: Activation trapezoid
A5: Rod outer diameter, D (mm) | B5: 7 | D5: Shear parameter, μ (MPa) | E5: 0.0473 | F5: Report input | H5: Wall thickness t (mm) | I5: Rod height H (mm) | K5: Eq. strain full-low | L5: 0.35 | M5: Activation trapezoid
A6: Buffer/base thickness, tb (mm) | B6: 1.75 | D6: Compressibility parameter, D1 (MPa⁻¹) | E6: 0.424 | F6: Report input | H6: 0.875 | I6: 1.75 | K6: Eq. strain full-high | L6: 0.55 | M6: Activation trapezoid
A7: Required indentation, δ (mm) | B7: 1.25 | D7: Initial bulk modulus, K (MPa) | E7: =2/E6 -> 4.7169811 | F7: =2/D1 | H7: 1.75 | I7: 3.5 | K7: Eq. strain zero-high | L7: 1 | M7: Activation trapezoid
A8: Array rows | B8: 3 | D8: Initial Young's modulus, E₀ (MPa) | E8: =9*E7*E5/(3*E7+E5) -> 0.14142727 | F8: =9Kμ/(3K+μ) | H8: 2.625 | I8: 5.25 | K8: Energy zero-low (mJ) | L8: 0.05 | M8: Activation trapezoid
A9: Array columns | B9: 3 | D9: Initial Poisson's ratio, ν₀ | E9: =(3*E7-2*E5)/(2*(3*E7+E5)) -> 0.4950029 | F9: Nearly incompressible | K9: Energy full-low (mJ) | L9: 0.2 | M9: Activation trapezoid
A10: Skin width (mm) | B10: 30 | D10: FEA elastomer | E10: Ecoflex 00-45 | F10: Unfilled material model | K10: Energy full-high (mJ) | L10: 0.4 | M10: Activation trapezoid
A11: Skin length (mm) | B11: 30 | D11: Indenter | E11: ABS | F11: Flexible body in reports | K11: Energy zero-high (mJ) | L11: 0.7 | M11: Activation trapezoid
A12: Common indenter width (mm) | B12: 4 | K12: Stress-localization proxy low | L12: 1.5 | M12: Ramp
A13: Rod count | B13: =B8*B9 -> 9 | K13: Stress-localization proxy high | L13: 3.5 | M13: Ramp
A14: Center-to-center pitch (mm) | B14: 9 | K14: Secant stiffness zero-low | L14: 0.08 | M14: Compliance trapezoid
A15: Inter-rod clear gap (mm) | B15: 2 | K15: Secant stiffness full-low | L15: 0.2 | M15: Compliance trapezoid
A16: Edge margin to skin boundary (mm) | B16: 2.5 | K16: Secant stiffness full-high | L16: 0.5 | M16: Compliance trapezoid
K17: Secant stiffness zero-high | L17: 1.2 | M17: Compliance trapezoid
A18: Model-scope warning | K18: Localization low | L18: 3 | M18: Ramp
A19: The analytical calculations are geometry-based proxies using the initial Ecoflex 00-45 modulus. The FEA reports also use unfilled Ecoflex 00-45, while the fabricated sensing skin contains a 70 wt% ZnS:Cu,Al/BaTiO₃ filler system in an Ecoflex/PDMS binder. Absolute force predictions must therefore be replaced by UTM-fitted composite properties before final validation. The analytical cylindrical formulas do not capture the rounded cap, wall ovalization, contact growth, or rod-to-base stress concentration. | K19: Localization high | L19: 8 | M19: Ramp
K20: Lateral ratio good | L20: 0.24 | M20: Inverse ramp
K21: Lateral ratio poor | L21: 0.38 | M21: Inverse ramp
K22: Eq. strain risk-good | L22: 0.55 | M22: Inverse ramp
K23: Eq. strain risk-poor | L23: 1 | M23: Inverse ramp
K24: H/t stable | L24: 3 | M24: Inverse ramp
K25: H/t unstable | L25: 6 | M25: Inverse ramp
K26: Hollow ratio zero-low | L26: 0.05 | M26: Geometry trapezoid
K27: Hollow ratio full-low | L27: 0.18 | M27: Geometry trapezoid
K28: Hollow ratio full-high | L28: 0.33 | M28: Geometry trapezoid
K29: Hollow ratio zero-high | L29: 0.6 | M29: Geometry trapezoid
K30: Cavity diameter low (mm) | L30: 1 | M30: Manufacturing ramp
K31: Cavity diameter full (mm) | L31: 3.5 | M31: Manufacturing ramp

Sheet Theoretical_Calc
A1: Theoretical Geometry and Structural Proxies
A3: Run | B3: Wall t (mm) | C3: Height H (mm) | D3: Inner diameter Di (mm) | E3: Annular area A (mm²) | F3: Second moment I (mm⁴) | G3: Polar moment J (mm⁴) | H3: Radius of gyration rg (mm) | I3: Hollow-area ratio | J3: H/t | K3: H/rg | L3: Nominal δ/H | M3: Linear axial k (N/mm) | N3: Linear compliance (mm/N) | O3: Lateral k proxy (N/mm) | P3: Euler Pcr proxy (N) | Q3: CAD rod volume (mm³) | R3: Straight annular volume A·H (mm³) | S3: CAD/A·H ratio
A4: 1 | B4: 0.875 | C4: 1.75 | D4: =Inputs_Theory!$B$5-2*B4 -> 5.25 | E4: =PI()/4*(Inputs_Theory!$B$5^2-D4^2) -> 16.836973 | F4: =PI()/64*(Inputs_Theory!$B$5^4-D4^4) -> 80.567547 | G4: =2*F4 -> 161.13509 | H4: =SQRT(F4/E4) -> 2.1875 | I4: =(D4/Inputs_Theory!$B$5)^2 -> 0.5625 | J4: =C4/B4 -> 2 | K4: =C4/H4 -> 0.8 | L4: =Inputs_Theory!$B$7/C4 -> 0.71428571 | M4: =Inputs_Theory!$E$8*E4/C4 -> 1.3606898 | N4: =1/M4 -> 0.73492134 | O4: =3*Inputs_Theory!$E$8*F4/C4^3 -> 6.3782336 | P4: =PI()^2*Inputs_Theory!$E$8*F4/(2*C4)^2 -> 9.1803021 | Q4: 27.005 | R4: =E4*C4 -> 29.464703 | S4: =Q4/R4 -> 0.91652035
A5: 2 | B5: 0.875 | C5: 3.5 | D5: =Inputs_Theory!$B$5-2*B5 -> 5.25 | E5: =PI()/4*(Inputs_Theory!$B$5^2-D5^2) -> 16.836973 | F5: =PI()/64*(Inputs_Theory!$B$5^4-D5^4) -> 80.567547 | G5: =2*F5 -> 161.13509 | H5: =SQRT(F5/E5) -> 2.1875 | I5: =(D5/Inputs_Theory!$B$5)^2 -> 0.5625 | J5: =C5/B5 -> 4 | K5: =C5/H5 -> 1.6 | L5: =Inputs_Theory!$B$7/C5 -> 0.35714286 | M5: =Inputs_Theory!$E$8*E5/C5 -> 0.68034492 | N5: =1/M5 -> 1.4698427 | O5: =3*Inputs_Theory!$E$8*F5/C5^3 -> 0.7972792 | P5: =PI()^2*Inputs_Theory!$E$8*F5/(2*C5)^2 -> 2.2950755 | Q5: 59.988 | R5: =E5*C5 -> 58.929406 | S5: =Q5/R5 -> 1.0179638
A6: 3 | B6: 0.875 | C6: 5.25 | D6: =Inputs_Theory!$B$5-2*B6 -> 5.25 | E6: =PI()/4*(Inputs_Theory!$B$5^2-D6^2) -> 16.836973 | F6: =PI()/64*(Inputs_Theory!$B$5^4-D6^4) -> 80.567547 | G6: =2*F6 -> 161.13509 | H6: =SQRT(F6/E6) -> 2.1875 | I6: =(D6/Inputs_Theory!$B$5)^2 -> 0.5625 | J6: =C6/B6 -> 6 | K6: =C6/H6 -> 2.4 | L6: =Inputs_Theory!$B$7/C6 -> 0.23809524 | M6: =Inputs_Theory!$E$8*E6/C6 -> 0.45356328 | N6: =1/M6 -> 2.204764 | O6: =3*Inputs_Theory!$E$8*F6/C6^3 -> 0.23623088 | P6: =PI()^2*Inputs_Theory!$E$8*F6/(2*C6)^2 -> 1.0200336 | Q6: 92.231 | R6: =E6*C6 -> 88.394109 | S6: =Q6/R6 -> 1.0434066
A7: 4 | B7: 1.75 | C7: 1.75 | D7: =Inputs_Theory!$B$5-2*B7 -> 3.5 | E7: =PI()/4*(Inputs_Theory!$B$5^2-D7^2) -> 28.863383 | F7: =PI()/64*(Inputs_Theory!$B$5^4-D7^4) -> 110.49264 | G7: =2*F7 -> 220.98527 | H7: =SQRT(F7/E7) -> 1.9565595 | I7: =(D7/Inputs_Theory!$B$5)^2 -> 0.25 | J7: =C7/B7 -> 1 | K7: =C7/H7 -> 0.89442719 | L7: =Inputs_Theory!$B$7/C7 -> 0.71428571 | M7: =Inputs_Theory!$E$8*E7/C7 -> 2.3326112 | N7: =1/M7 -> 0.42870411 | O7: =3*Inputs_Theory!$E$8*F7/C7^3 -> 8.7472918 | P7: =PI()^2*Inputs_Theory!$E$8*F7/(2*C7)^2 -> 12.590129 | Q7: 34.547 | R7: =E7*C7 -> 50.510919 | S7: =Q7/R7 -> 0.68395112
A8: 5 | B8: 1.75 | C8: 3.5 | D8: =Inputs_Theory!$B$5-2*B8 -> 3.5 | E8: =PI()/4*(Inputs_Theory!$B$5^2-D8^2) -> 28.863383 | F8: =PI()/64*(Inputs_Theory!$B$5^4-D8^4) -> 110.49264 | G8: =2*F8 -> 220.98527 | H8: =SQRT(F8/E8) -> 1.9565595 | I8: =(D8/Inputs_Theory!$B$5)^2 -> 0.25 | J8: =C8/B8 -> 2 | K8: =C8/H8 -> 1.7888544 | L8: =Inputs_Theory!$B$7/C8 -> 0.35714286 | M8: =Inputs_Theory!$E$8*E8/C8 -> 1.1663056 | N8: =1/M8 -> 0.85740823 | O8: =3*Inputs_Theory!$E$8*F8/C8^3 -> 1.0934115 | P8: =PI()^2*Inputs_Theory!$E$8*F8/(2*C8)^2 -> 3.1475321 | Q8: 74.166 | R8: =E8*C8 -> 101.02184 | S8: =Q8/R8 -> 0.73415809
A9: 6 | B9: 1.75 | C9: 5.25 | D9: =Inputs_Theory!$B$5-2*B9 -> 3.5 | E9: =PI()/4*(Inputs_Theory!$B$5^2-D9^2) -> 28.863383 | F9: =PI()/64*(Inputs_Theory!$B$5^4-D9^4) -> 110.49264 | G9: =2*F9 -> 220.98527 | H9: =SQRT(F9/E9) -> 1.9565595 | I9: =(D9/Inputs_Theory!$B$5)^2 -> 0.25 | J9: =C9/B9 -> 3 | K9: =C9/H9 -> 2.6832816 | L9: =Inputs_Theory!$B$7/C9 -> 0.23809524 | M9: =Inputs_Theory!$E$8*E9/C9 -> 0.77753705 | N9: =1/M9 -> 1.2861123 | O9: =3*Inputs_Theory!$E$8*F9/C9^3 -> 0.32397377 | P9: =PI()^2*Inputs_Theory!$E$8*F9/(2*C9)^2 -> 1.3989032 | Q9: 126.16 | R9: =E9*C9 -> 151.53276 | S9: =Q9/R9 -> 0.83255925
A10: 7 | B10: 2.625 | C10: 1.75 | D10: =Inputs_Theory!$B$5-2*B10 -> 1.75 | E10: =PI()/4*(Inputs_Theory!$B$5^2-D10^2) -> 36.079228 | F10: =PI()/64*(Inputs_Theory!$B$5^4-D10^4) -> 117.39843 | G10: =2*F10 -> 234.79685 | H10: =SQRT(F10/E10) -> 1.8038587 | I10: =(D10/Inputs_Theory!$B$5)^2 -> 0.0625 | J10: =C10/B10 -> 0.66666667 | K10: =C10/H10 -> 0.9701425 | L10: =Inputs_Theory!$B$7/C10 -> 0.71428571 | M10: =Inputs_Theory!$E$8*E10/C10 -> 2.9157639 | N10: =1/M10 -> 0.34296329 | O10: =3*Inputs_Theory!$E$8*F10/C10^3 -> 9.2939976 | P10: =PI()^2*Inputs_Theory!$E$8*F10/(2*C10)^2 -> 13.377012 | Q10: 38.579 | R10: =E10*C10 -> 63.138649 | S10: =Q10/R10 -> 0.61102036
A11: 8 | B11: 2.625 | C11: 3.5 | D11: =Inputs_Theory!$B$5-2*B11 -> 1.75 | E11: =PI()/4*(Inputs_Theory!$B$5^2-D11^2) -> 36.079228 | F11: =PI()/64*(Inputs_Theory!$B$5^4-D11^4) -> 117.39843 | G11: =2*F11 -> 234.79685 | H11: =SQRT(F11/E11) -> 1.8038587 | I11: =(D11/Inputs_Theory!$B$5)^2 -> 0.0625 | J11: =C11/B11 -> 1.3333333 | K11: =C11/H11 -> 1.940285 | L11: =Inputs_Theory!$B$7/C11 -> 0.35714286 | M11: =Inputs_Theory!$E$8*E11/C11 -> 1.457882 | N11: =1/M11 -> 0.68592658 | O11: =3*Inputs_Theory!$E$8*F11/C11^3 -> 1.1617497 | P11: =PI()^2*Inputs_Theory!$E$8*F11/(2*C11)^2 -> 3.3442529 | Q11: 85.128 | R11: =E11*C11 -> 126.2773 | S11: =Q11/R11 -> 0.67413542
A12: 9 | B12: 2.625 | C12: 5.25 | D12: =Inputs_Theory!$B$5-2*B12 -> 1.75 | E12: =PI()/4*(Inputs_Theory!$B$5^2-D12^2) -> 36.079228 | F12: =PI()/64*(Inputs_Theory!$B$5^4-D12^4) -> 117.39843 | G12: =2*F12 -> 234.79685 | H12: =SQRT(F12/E12) -> 1.8038587 | I12: =(D12/Inputs_Theory!$B$5)^2 -> 0.0625 | J12: =C12/B12 -> 2 | K12: =C12/H12 -> 2.9104275 | L12: =Inputs_Theory!$B$7/C12 -> 0.23809524 | M12: =Inputs_Theory!$E$8*E12/C12 -> 0.97192132 | N12: =1/M12 -> 1.0288899 | O12: =3*Inputs_Theory!$E$8*F12/C12^3 -> 0.34422213 | P12: =PI()^2*Inputs_Theory!$E$8*F12/(2*C12)^2 -> 1.4863346 | Q12: 148.61 | R12: =E12*C12 -> 189.41595 | S12: =Q12/R12 -> 0.78456963

Sheet FEA_Setup_QA
A1: FEA Setup Audit and Comparability Check
A3: Run | B3: Solve status | C3: Target δ (mm) | D3: Last reported |Uz|min (mm) | E3: Indenter (mm) | F3: Base volume (mm³) | G3: Rod volume each (mm³) | H3: Model volume (mm³) | I3: Nodes | J3: Elements | K3: Contact | L3: Material | M3: QA finding | N3: Screening use
A4: 1 | B4: Solved | C4: 1.25 | D4: 1.25 | E4: 4 | F4: 1234.6 | G4: 27.005 | H4: 2085.6 | I4: 5543 | J4: 1959 | K4: Frictionless / asymmetric; bonded rods-base | L4: Ecoflex 00-45; ABS indenter | M4: Updated model now uses the common 4 × 4 mm indenter; directly comparable. | N4: Direct comparison
A5: 2 | B5: Solved | C5: 1.25 | D5: 1.25 | E5: 4 | F5: 1234.6 | G5: 59.988 | H5: 2382.5 | I5: 11909 | J5: 5815 | K5: Frictionless / asymmetric; bonded rods-base | L5: Ecoflex 00-45; ABS indenter | M5: No major setup mismatch found; automatic mesh still needs convergence verification. | N5: Direct comparison
A6: 3 | B6: Solved | C6: 1.25 | D6: 1.25 | E6: 4 | F6: 1234.6 | G6: 92.231 | H6: 2672.7 | I6: 10388 | J6: 4750 | K6: Frictionless / asymmetric; bonded rods-base | L6: Ecoflex 00-45; ABS indenter | M6: No major setup mismatch found; automatic mesh still needs convergence verification. | N6: Direct comparison
A7: 4 | B7: Solved | C7: 1.25 | D7: 1.25 | E7: 4 | F7: 1424.4 | G7: 34.547 | H7: 2343.4 | I7: 7413 | J7: 2829 | K7: Frictionless / asymmetric; bonded rods-base | L7: Ecoflex 00-45; ABS indenter | M7: Solved, but lateral directional-deformation scoping differs from several other reports; treat lateral ratio with moderate caution. | N7: Direct comparison
A8: 5 | B8: Solved | C8: 1.25 | D8: 1.25 | E8: 4 | F8: 1424.4 | G8: 74.166 | H8: 2699.9 | I8: 6869 | J8: 2574 | K8: Frictionless / asymmetric; bonded rods-base | L8: Ecoflex 00-45; ABS indenter | M8: Updated curve engages immediately; the previous delayed-contact concern is resolved. | N8: Direct comparison
A9: 6 | B9: Solved | C9: 1.25 | D9: 1.25 | E9: 4 | F9: 1424.4 | G9: 126.16 | H9: 3167.8 | I9: 8028 | J9: 3136 | K9: Frictionless / asymmetric; bonded rods-base | L9: Ecoflex 00-45; ABS indenter | M9: No major setup mismatch found; directly comparable. | N9: Direct comparison
A10: 7 | B10: Failed | C10: 1.25 | D10: 1.2467 | E10: 4 | F10: 1537.4 | G10: 38.579 | H10: 2492.6 | I10: 9992 | J10: 4242 | K10: Frictionless / asymmetric; bonded rods-base | L10: Ecoflex 00-45; ABS indenter | M10: Report is not finalized and the nonlinear solution failed. The last displayed state reports |Uz|min = 1.2467 mm; its strain, stress, energy, and force outputs are diagnostic only and not rankable. | N10: Diagnostic only — score forced to zero
A11: 8 | B11: Solved | C11: 1.25 | D11: 1.25 | E11: 4 | F11: 1537.4 | G11: 85.128 | H11: 2911.5 | I11: 8217 | J11: 3404 | K11: Frictionless / asymmetric; bonded rods-base | L11: Ecoflex 00-45; ABS indenter | M11: Updated curve engages immediately; old delayed-contact concern is resolved. A separate stress-intensity object has different scoping and is excluded. | N11: Direct comparison
A12: 9 | B12: Solved | C12: 1.25 | D12: 1.25 | E12: 4 | F12: 1537.4 | G12: 148.61 | H12: 3482.8 | I12: 9493 | J12: 4139 | K12: Frictionless / asymmetric; bonded rods-base | L12: Ecoflex 00-45; ABS indenter | M12: Solved and directly comparable; near-solid cavity remains a mechanism limitation. | N12: Direct comparison
A15: Common nonlinear setup and limitations
A16: All reports use large deflection, automatic time stepping, a frictionless indenter contact, and a Neo-Hookean Ecoflex 00-45 model. Run 7 is especially well documented as a genuine target failure: it used two load steps, 200 initial / 100 minimum / 2000 maximum substeps, Full Newton–Raphson, and Line Search On, yet the report remained 'Solve Failed' and 'Not Finalized'. No report contains a formal mesh-convergence study, and some result objects use different scoping. Cross-run ranking therefore relies only on the common equivalent strain, equivalent stress, energy, reaction force, and global displacement outputs.

Sheet FEA_Raw
A1: Cross-Run FEA Results Extracted from ANSYS Reports
A3: Run | B3: Status | C3: Total deformation max (mm) | D3: Ux min | E3: Ux max | F3: Uy min | G3: Uy max | H3: Uz min | I3: Uz max | J3: Eq. strain max | K3: Eq. strain avg | L3: Eq. stress max (MPa) | M3: Eq. stress avg (MPa) | N3: Total strain energy (mJ) | O3: Max element energy (mJ) | P3: Fx (N) | Q3: Fy (N) | R3: Fz (N) | S3: Force total (N) | T3: Moment total (N·mm)
A4: 1 | B4: Solved | C4: 1.2879 | D4: -0.30586 | E4: 0.30794 | F4: -0.26208 | G4: 0.24323 | H4: -1.2877 | I4: 0.071349 | J4: 0.38402 | K4: 0.061812 | L4: 0.041209 | M4: 0.0058107 | N4: 0.18595 | O4: 0.0095731 | P4: -0.0026995 | Q4: 0.0063496 | R4: -0.39382 | S4: 0.39388 | T4: 0.06266
A5: 2 | B5: Solved | C5: 1.2723 | D5: -0.29508 | E5: 0.302 | F5: -0.284 | G5: 0.26686 | H5: -1.2722 | I5: 0.030519 | J5: 0.39039 | K5: 0.1179 | L5: 0.047958 | M5: 0.01439 | N5: 0.14115 | O5: 0.0016088 | P5: 0.00031096 | Q5: 0.00088709 | R5: -0.25363 | S5: 0.25363 | T5: 0.0056734
A6: 3 | B6: Solved | C6: 1.2653 | D6: -0.31707 | E6: 0.29511 | F6: -0.29433 | G6: 0.29072 | H6: -1.2652 | I6: 0.015601 | J6: 0.36118 | K6: 0.078214 | L6: 0.044558 | M6: 0.0094931 | N6: 0.12106 | O6: 0.0023575 | P6: -0.00074615 | Q6: 0.00019182 | R6: -0.18224 | S6: 0.18224 | T6: 0.0058236
A7: 4 | B7: Solved | C7: 1.2875 | D7: -0.4575 | E7: 0.42382 | F7: -0.42261 | G7: 0.40017 | H7: -1.2669 | I7: 0.094296 | J7: 0.54173 | K7: 0.065235 | L7: 0.068249 | M7: 0.0074679 | N7: 0.52259 | O7: 0.023462 | P7: -0.0074968 | Q7: 1.8146e-05 | R7: -1.1661 | S7: 1.1662 | T7: 0.023793
A8: 5 | B8: Solved | C8: 1.2784 | D8: -0.31704 | E8: 0.34379 | F8: -0.35807 | G8: 0.34683 | H8: -1.2772 | I8: 0.057538 | J8: 0.39425 | K8: 0.051909 | L8: 0.047683 | M8: 0.0061699 | N8: 0.31364 | O8: 0.0071484 | P8: 0.0093836 | Q8: -0.0026448 | R8: -0.52946 | S8: 0.52955 | T8: 0.0092367
A9: 6 | B9: Solved | C9: 1.25 | D9: -0.29568 | E9: 0.31532 | F9: -0.29724 | G9: 0.32022 | H9: -1.25 | I9: 0.019165 | J9: 0.41045 | K9: 0.039758 | L9: 0.049149 | M9: 0.0047938 | N9: 0.24758 | O9: 0.006219 | P9: -0.00054565 | Q9: 0.001663 | R9: -0.38815 | S9: 0.38815 | T9: 0.015359
A10: 7 | B10: Failed | C10: 1.2467 | D10: -0.41507 | E10: 0.40913 | F10: -0.41465 | G10: 0.40914 | H10: -1.2467 | I10: 0.12143 | J10: 1.0378 | K10: 0.16068 | L10: 0.17953 | M10: 0.020483 | N10: 0.67089 | O10: 0.024541 | P10: 0.00057351 | Q10: -0.0014033 | R10: -1.621 | S10: 1.621 | T10: 0.066278
A11: 8 | B11: Solved | C11: 1.2633 | D11: -0.34832 | E11: 0.31265 | F11: -0.30468 | G11: 0.34945 | H11: -1.2629 | I11: 0.046755 | J11: 0.54173 | K11: 0.077489 | L11: 0.0664 | M11: 0.0093922 | N11: 0.39134 | O11: 0.00549 | P11: -0.0061943 | Q11: 0.001205 | R11: -0.80258 | S11: 0.8026 | T11: 0.021522
A12: 9 | B12: Solved | C12: 1.2922 | D12: -0.28341 | E12: 0.26526 | F12: -0.28179 | G12: 0.27813 | H12: -1.2913 | I12: 0.031253 | J12: 0.44393 | K12: 0.058664 | L12: 0.053375 | M12: 0.0072144 | N12: 0.32715 | O12: 0.0043773 | P12: -0.00025991 | Q12: -0.0021355 | R12: -0.58161 | S12: 0.58161 | T12: 0.013802

Sheet Derived_Metrics
A1: Derived FEA Performance Metrics
A3: Run | B3: Wall t | C3: Height H | D3: Status | E3: |Fz| (N) | F3: Secant k (N/mm) | G3: Max lateral def. (mm) | H3: Lateral ratio | I3: Strain localization | J3: Stress localization | K3: Nominal axial stress (MPa) | L3: Stress-localization proxy | M3: Energy / force (mm) | N3: Work ratio 2U/Fδ | O3: FEA / linear k | P3: Theoretical lateral k | Q3: H/t | R3: Di (mm) | S3: Hollow ratio | T3: Eq. strain max | U3: Total energy (mJ) | V3: Convergence flag
A4: =FEA_Raw!A4 -> 1 | B4: =Theoretical_Calc!B4 -> 0.875 | C4: =Theoretical_Calc!C4 -> 1.75 | D4: =FEA_Raw!B4 -> Solved | E4: =ABS(FEA_Raw!R4) -> 0.39382 | F4: =E4/Inputs_Theory!$B$7 -> 0.315056 | G4: =MAX(-FEA_Raw!D4,FEA_Raw!E4,-FEA_Raw!F4,FEA_Raw!G4) -> 0.30794 | H4: =G4/ABS(FEA_Raw!H4) -> 0.23913955 | I4: =FEA_Raw!J4/FEA_Raw!K4 -> 6.2127095 | J4: =FEA_Raw!L4/FEA_Raw!M4 -> 7.0919166 | K4: =E4/Theoretical_Calc!E4 -> 0.02339019 | L4: =FEA_Raw!L4/K4 -> 1.761807 | M4: =FEA_Raw!N4/E4 -> 0.47217003 | N4: =2*FEA_Raw!N4/(E4*Inputs_Theory!$B$7) -> 0.75547204 | O4: =F4/Theoretical_Calc!M4 -> 0.23154138 | P4: =Theoretical_Calc!O4 -> 6.3782336 | Q4: =Theoretical_Calc!J4 -> 2 | R4: =Theoretical_Calc!D4 -> 5.25 | S4: =Theoretical_Calc!I4 -> 0.5625 | T4: =FEA_Raw!J4 -> 0.38402 | U4: =FEA_Raw!N4 -> 0.18595 | V4: =IF(D4="Solved",1,0) -> 1
A5: =FEA_Raw!A5 -> 2 | B5: =Theoretical_Calc!B5 -> 0.875 | C5: =Theoretical_Calc!C5 -> 3.5 | D5: =FEA_Raw!B5 -> Solved | E5: =ABS(FEA_Raw!R5) -> 0.25363 | F5: =E5/Inputs_Theory!$B$7 -> 0.202904 | G5: =MAX(-FEA_Raw!D5,FEA_Raw!E5,-FEA_Raw!F5,FEA_Raw!G5) -> 0.302 | H5: =G5/ABS(FEA_Raw!H5) -> 0.23738406 | I5: =FEA_Raw!J5/FEA_Raw!K5 -> 3.3111959 | J5: =FEA_Raw!L5/FEA_Raw!M5 -> 3.3327311 | K5: =E5/Theoretical_Calc!E5 -> 0.015063872 | L5: =FEA_Raw!L5/K5 -> 3.1836437 | M5: =FEA_Raw!N5/E5 -> 0.55651934 | N5: =2*FEA_Raw!N5/(E5*Inputs_Theory!$B$7) -> 0.89043094 | O5: =F5/Theoretical_Calc!M5 -> 0.29823696 | P5: =Theoretical_Calc!O5 -> 0.7972792 | Q5: =Theoretical_Calc!J5 -> 4 | R5: =Theoretical_Calc!D5 -> 5.25 | S5: =Theoretical_Calc!I5 -> 0.5625 | T5: =FEA_Raw!J5 -> 0.39039 | U5: =FEA_Raw!N5 -> 0.14115 | V5: =IF(D5="Solved",1,0) -> 1
A6: =FEA_Raw!A6 -> 3 | B6: =Theoretical_Calc!B6 -> 0.875 | C6: =Theoretical_Calc!C6 -> 5.25 | D6: =FEA_Raw!B6 -> Solved | E6: =ABS(FEA_Raw!R6) -> 0.18224 | F6: =E6/Inputs_Theory!$B$7 -> 0.145792 | G6: =MAX(-FEA_Raw!D6,FEA_Raw!E6,-FEA_Raw!F6,FEA_Raw!G6) -> 0.31707 | H6: =G6/ABS(FEA_Raw!H6) -> 0.2506086 | I6: =FEA_Raw!J6/FEA_Raw!K6 -> 4.6178434 | J6: =FEA_Raw!L6/FEA_Raw!M6 -> 4.6937249 | K6: =E6/Theoretical_Calc!E6 -> 0.010823798 | L6: =FEA_Raw!L6/K6 -> 4.1166695 | M6: =FEA_Raw!N6/E6 -> 0.66428885 | N6: =2*FEA_Raw!N6/(E6*Inputs_Theory!$B$7) -> 1.0628622 | O6: =F6/Theoretical_Calc!M6 -> 0.32143696 | P6: =Theoretical_Calc!O6 -> 0.23623088 | Q6: =Theoretical_Calc!J6 -> 6 | R6: =Theoretical_Calc!D6 -> 5.25 | S6: =Theoretical_Calc!I6 -> 0.5625 | T6: =FEA_Raw!J6 -> 0.36118 | U6: =FEA_Raw!N6 -> 0.12106 | V6: =IF(D6="Solved",1,0) -> 1
A7: =FEA_Raw!A7 -> 4 | B7: =Theoretical_Calc!B7 -> 1.75 | C7: =Theoretical_Calc!C7 -> 1.75 | D7: =FEA_Raw!B7 -> Solved | E7: =ABS(FEA_Raw!R7) -> 1.1661 | F7: =E7/Inputs_Theory!$B$7 -> 0.93288 | G7: =MAX(-FEA_Raw!D7,FEA_Raw!E7,-FEA_Raw!F7,FEA_Raw!G7) -> 0.4575 | H7: =G7/ABS(FEA_Raw!H7) -> 0.36111769 | I7: =FEA_Raw!J7/FEA_Raw!K7 -> 8.3042845 | J7: =FEA_Raw!L7/FEA_Raw!M7 -> 9.1389815 | K7: =E7/Theoretical_Calc!E7 -> 0.04040067 | L7: =FEA_Raw!L7/K7 -> 1.6893037 | M7: =FEA_Raw!N7/E7 -> 0.44815196 | N7: =2*FEA_Raw!N7/(E7*Inputs_Theory!$B$7) -> 0.71704314 | O7: =F7/Theoretical_Calc!M7 -> 0.39992949 | P7: =Theoretical_Calc!O7 -> 8.7472918 | Q7: =Theoretical_Calc!J7 -> 1 | R7: =Theoretical_Calc!D7 -> 3.5 | S7: =Theoretical_Calc!I7 -> 0.25 | T7: =FEA_Raw!J7 -> 0.54173 | U7: =FEA_Raw!N7 -> 0.52259 | V7: =IF(D7="Solved",1,0) -> 1
A8: =FEA_Raw!A8 -> 5 | B8: =Theoretical_Calc!B8 -> 1.75 | C8: =Theoretical_Calc!C8 -> 3.5 | D8: =FEA_Raw!B8 -> Solved | E8: =ABS(FEA_Raw!R8) -> 0.52946 | F8: =E8/Inputs_Theory!$B$7 -> 0.423568 | G8: =MAX(-FEA_Raw!D8,FEA_Raw!E8,-FEA_Raw!F8,FEA_Raw!G8) -> 0.35807 | H8: =G8/ABS(FEA_Raw!H8) -> 0.28035547 | I8: =FEA_Raw!J8/FEA_Raw!K8 -> 7.5950221 | J8: =FEA_Raw!L8/FEA_Raw!M8 -> 7.7283262 | K8: =E8/Theoretical_Calc!E8 -> 0.018343657 | L8: =FEA_Raw!L8/K8 -> 2.5994271 | M8: =FEA_Raw!N8/E8 -> 0.59237714 | N8: =2*FEA_Raw!N8/(E8*Inputs_Theory!$B$7) -> 0.94780342 | O8: =F8/Theoretical_Calc!M8 -> 0.36317069 | P8: =Theoretical_Calc!O8 -> 1.0934115 | Q8: =Theoretical_Calc!J8 -> 2 | R8: =Theoretical_Calc!D8 -> 3.5 | S8: =Theoretical_Calc!I8 -> 0.25 | T8: =FEA_Raw!J8 -> 0.39425 | U8: =FEA_Raw!N8 -> 0.31364 | V8: =IF(D8="Solved",1,0) -> 1
A9: =FEA_Raw!A9 -> 6 | B9: =Theoretical_Calc!B9 -> 1.75 | C9: =Theoretical_Calc!C9 -> 5.25 | D9: =FEA_Raw!B9 -> Solved | E9: =ABS(FEA_Raw!R9) -> 0.38815 | F9: =E9/Inputs_Theory!$B$7 -> 0.31052 | G9: =MAX(-FEA_Raw!D9,FEA_Raw!E9,-FEA_Raw!F9,FEA_Raw!G9) -> 0.32022 | H9: =G9/ABS(FEA_Raw!H9) -> 0.256176 | I9: =FEA_Raw!J9/FEA_Raw!K9 -> 10.323708 | J9: =FEA_Raw!L9/FEA_Raw!M9 -> 10.252618 | K9: =E9/Theoretical_Calc!E9 -> 0.013447835 | L9: =FEA_Raw!L9/K9 -> 3.6547891 | M9: =FEA_Raw!N9/E9 -> 0.63784619 | N9: =2*FEA_Raw!N9/(E9*Inputs_Theory!$B$7) -> 1.0205539 | O9: =F9/Theoretical_Calc!M9 -> 0.3993636 | P9: =Theoretical_Calc!O9 -> 0.32397377 | Q9: =Theoretical_Calc!J9 -> 3 | R9: =Theoretical_Calc!D9 -> 3.5 | S9: =Theoretical_Calc!I9 -> 0.25 | T9: =FEA_Raw!J9 -> 0.41045 | U9: =FEA_Raw!N9 -> 0.24758 | V9: =IF(D9="Solved",1,0) -> 1
A10: =FEA_Raw!A10 -> 7 | B10: =Theoretical_Calc!B10 -> 2.625 | C10: =Theoretical_Calc!C10 -> 1.75 | D10: =FEA_Raw!B10 -> Failed | E10: =ABS(FEA_Raw!R10) -> 1.621 | F10: =E10/Inputs_Theory!$B$7 -> 1.2968 | G10: =MAX(-FEA_Raw!D10,FEA_Raw!E10,-FEA_Raw!F10,FEA_Raw!G10) -> 0.41507 | H10: =G10/ABS(FEA_Raw!H10) -> 0.33293495 | I10: =FEA_Raw!J10/FEA_Raw!K10 -> 6.4588001 | J10: =FEA_Raw!L10/FEA_Raw!M10 -> 8.7648294 | K10: =E10/Theoretical_Calc!E10 -> 0.044928899 | L10: =FEA_Raw!L10/K10 -> 3.9958691 | M10: =FEA_Raw!N10/E10 -> 0.41387415 | N10: =2*FEA_Raw!N10/(E10*Inputs_Theory!$B$7) -> 0.66219864 | O10: =F10/Theoretical_Calc!M10 -> 0.4447548 | P10: =Theoretical_Calc!O10 -> 9.2939976 | Q10: =Theoretical_Calc!J10 -> 0.66666667 | R10: =Theoretical_Calc!D10 -> 1.75 | S10: =Theoretical_Calc!I10 -> 0.0625 | T10: =FEA_Raw!J10 -> 1.0378 | U10: =FEA_Raw!N10 -> 0.67089 | V10: =IF(D10="Solved",1,0) -> 0
A11: =FEA_Raw!A11 -> 8 | B11: =Theoretical_Calc!B11 -> 2.625 | C11: =Theoretical_Calc!C11 -> 3.5 | D11: =FEA_Raw!B11 -> Solved | E11: =ABS(FEA_Raw!R11) -> 0.80258 | F11: =E11/Inputs_Theory!$B$7 -> 0.642064 | G11: =MAX(-FEA_Raw!D11,FEA_Raw!E11,-FEA_Raw!F11,FEA_Raw!G11) -> 0.34945 | H11: =G11/ABS(FEA_Raw!H11) -> 0.27670441 | I11: =FEA_Raw!J11/FEA_Raw!K11 -> 6.9910568 | J11: =FEA_Raw!L11/FEA_Raw!M11 -> 7.0696961 | K11: =E11/Theoretical_Calc!E11 -> 0.022244933 | L11: =FEA_Raw!L11/K11 -> 2.9849495 | M11: =FEA_Raw!N11/E11 -> 0.48760248 | N11: =2*FEA_Raw!N11/(E11*Inputs_Theory!$B$7) -> 0.78016397 | O11: =F11/Theoretical_Calc!M11 -> 0.44040877 | P11: =Theoretical_Calc!O11 -> 1.1617497 | Q11: =Theoretical_Calc!J11 -> 1.3333333 | R11: =Theoretical_Calc!D11 -> 1.75 | S11: =Theoretical_Calc!I11 -> 0.0625 | T11: =FEA_Raw!J11 -> 0.54173 | U11: =FEA_Raw!N11 -> 0.39134 | V11: =IF(D11="Solved",1,0) -> 1
A12: =FEA_Raw!A12 -> 9 | B12: =Theoretical_Calc!B12 -> 2.625 | C12: =Theoretical_Calc!C12 -> 5.25 | D12: =FEA_Raw!B12 -> Solved | E12: =ABS(FEA_Raw!R12) -> 0.58161 | F12: =E12/Inputs_Theory!$B$7 -> 0.465288 | G12: =MAX(-FEA_Raw!D12,FEA_Raw!E12,-FEA_Raw!F12,FEA_Raw!G12) -> 0.28341 | H12: =G12/ABS(FEA_Raw!H12) -> 0.2194765 | I12: =FEA_Raw!J12/FEA_Raw!K12 -> 7.5673326 | J12: =FEA_Raw!L12/FEA_Raw!M12 -> 7.3983976 | K12: =E12/Theoretical_Calc!E12 -> 0.016120356 | L12: =FEA_Raw!L12/K12 -> 3.3110311 | M12: =FEA_Raw!N12/E12 -> 0.56249033 | N12: =2*FEA_Raw!N12/(E12*Inputs_Theory!$B$7) -> 0.89998453 | O12: =F12/Theoretical_Calc!M12 -> 0.47873011 | P12: =Theoretical_Calc!O12 -> 0.34422213 | Q12: =Theoretical_Calc!J12 -> 2 | R12: =Theoretical_Calc!D12 -> 1.75 | S12: =Theoretical_Calc!I12 -> 0.0625 | T12: =FEA_Raw!J12 -> 0.44393 | U12: =FEA_Raw!N12 -> 0.32715 | V12: =IF(D12="Solved",1,0) -> 1

Sheet Combined_Ranking
A1: Combined Theoretical + FEA Design Screening
A3: Run | B3: Wall t | C3: Height H | D3: Status | E3: Activation | F3: Compliance | G3: Localization | H3: Stability | I3: Hollow / fabrication | J3: Balanced score | K3: Sensitivity-first | L3: Durability-first | M3: Balanced rank | N3: Durability rank | O3: Decision class | P3: Recommended role
A4: =Derived_Metrics!A4 -> 1 | B4: =Derived_Metrics!B4 -> 0.875 | C4: =Derived_Metrics!C4 -> 1.75 | D4: =Derived_Metrics!D4 -> Solved | E4: =IF(Derived_Metrics!V4=0,0,0.45*(IF(Derived_Metrics!T4<=Inputs_Theory!$L$4,0,IF(Derived_Metrics!T4<Inputs_Theory!$L$5,(Derived_Metrics!T4-Inputs_Theory!$L$4)/(Inputs_Theory!$L$5-Inputs_Theory!$L$4),IF(Derived_Metrics!T4<=Inputs_Theory!$L$6,1,IF(Derived_Metrics!T4<Inputs_Theory!$L$7,(Inputs_Theory!$L$7-Derived_Metrics!T4)/(Inputs_Theory!$L$7-Inputs_Theory!$L$6),0)))))+0.35*(IF(Derived_Metrics!U4<=Inputs_Theory!$L$8,0,IF(Derived_Metrics!U4<Inputs_Theory!$L$9,(Derived_Metrics!U4-Inputs_Theory!$L$8)/(Inputs_Theory!$L$9-Inputs_Theory!$L$8),IF(Derived_Metrics!U4<=Inputs_Theory!$L$10,1,IF(Derived_Metrics!U4<Inputs_Theory!$L$11,(Inputs_Theory!$L$11-Derived_Metrics!U4)/(Inputs_Theory!$L$11-Inputs_Theory!$L$10),0)))))+0.2*(MAX(0,MIN(1,(Derived_Metrics!L4-Inputs_Theory!$L$12)/(Inputs_Theory!$L$13-Inputs_Theory!$L$12))))) -> 0.79339736 | F4: =IF(Derived_Metrics!V4=0,0,IF(Derived_Metrics!F4<=Inputs_Theory!$L$14,0,IF(Derived_Metrics!F4<Inputs_Theory!$L$15,(Derived_Metrics!F4-Inputs_Theory!$L$14)/(Inputs_Theory!$L$15-Inputs_Theory!$L$14),IF(Derived_Metrics!F4<=Inputs_Theory!$L$16,1,IF(Derived_Metrics!F4<Inputs_Theory!$L$17,(Inputs_Theory!$L$17-Derived_Metrics!F4)/(Inputs_Theory!$L$17-Inputs_Theory!$L$16),0))))) -> 1 | G4: =IF(Derived_Metrics!V4=0,0,0.5*(MAX(0,MIN(1,(Derived_Metrics!I4-Inputs_Theory!$L$18)/(Inputs_Theory!$L$19-Inputs_Theory!$L$18))))+0.5*(MAX(0,MIN(1,(Inputs_Theory!$L$21-Derived_Metrics!H4)/(Inputs_Theory!$L$21-Inputs_Theory!$L$20))))) -> 0.82127095 | H4: =IF(Derived_Metrics!V4=0,0,0.35*Derived_Metrics!V4+0.25*MIN(1,Derived_Metrics!P4/Derived_Metrics!$P$8)+0.25*(MAX(0,MIN(1,(Inputs_Theory!$L$23-Derived_Metrics!T4)/(Inputs_Theory!$L$23-Inputs_Theory!$L$22))))+0.15*(MAX(0,MIN(1,(Inputs_Theory!$L$25-Derived_Metrics!Q4)/(Inputs_Theory!$L$25-Inputs_Theory!$L$24))))) -> 1 | I4: =IF(Derived_Metrics!V4=0,0,0.5*(IF(Derived_Metrics!S4<=Inputs_Theory!$L$26,0,IF(Derived_Metrics!S4<Inputs_Theory!$L$27,(Derived_Metrics!S4-Inputs_Theory!$L$26)/(Inputs_Theory!$L$27-Inputs_Theory!$L$26),IF(Derived_Metrics!S4<=Inputs_Theory!$L$28,1,IF(Derived_Metrics!S4<Inputs_Theory!$L$29,(Inputs_Theory!$L$29-Derived_Metrics!S4)/(Inputs_Theory!$L$29-Inputs_Theory!$L$28),0)))))+0.3*(IF(B4=0.875,0.6,IF(B4=1.75,1,0.8)))+0.2*(MAX(0,MIN(1,(Derived_Metrics!R4-Inputs_Theory!$L$30)/(Inputs_Theory!$L$31-Inputs_Theory!$L$30))))) -> 0.44944444 | J4: =IF(Derived_Metrics!V4=0,0,0.3*E4+0.2*F4+0.2*G4+0.15*H4+0.15*I4) -> 0.81969007 | K4: =IF(Derived_Metrics!V4=0,0,0.4*E4+0.25*F4+0.2*G4+0.05*H4+0.1*I4) -> 0.82655758 | L4: =IF(Derived_Metrics!V4=0,0,0.2*E4+0.1*F4+0.15*G4+0.3*H4+0.25*I4) -> 0.79423123 | M4: =_xlfn.RANK.EQ(J4,$J$4:$J$12,0) -> 4 | N4: =_xlfn.SINGLE(_xlfn.RANK.EQ(L4,$L$4:$L$12,0)) -> 4 | O4: THIN-WALL EXTREME | P4: Retain only as a highly hollow compliance/sensitivity control.
A5: =Derived_Metrics!A5 -> 2 | B5: =Derived_Metrics!B5 -> 0.875 | C5: =Derived_Metrics!C5 -> 3.5 | D5: =Derived_Metrics!D5 -> Solved | E5: =IF(Derived_Metrics!V5=0,0,0.45*(IF(Derived_Metrics!T5<=Inputs_Theory!$L$4,0,IF(Derived_Metrics!T5<Inputs_Theory!$L$5,(Derived_Metrics!T5-Inputs_Theory!$L$4)/(Inputs_Theory!$L$5-Inputs_Theory!$L$4),IF(Derived_Metrics!T5<=Inputs_Theory!$L$6,1,IF(Derived_Metrics!T5<Inputs_Theory!$L$7,(Inputs_Theory!$L$7-Derived_Metrics!T5)/(Inputs_Theory!$L$7-Inputs_Theory!$L$6),0)))))+0.35*(IF(Derived_Metrics!U5<=Inputs_Theory!$L$8,0,IF(Derived_Metrics!U5<Inputs_Theory!$L$9,(Derived_Metrics!U5-Inputs_Theory!$L$8)/(Inputs_Theory!$L$9-Inputs_Theory!$L$8),IF(Derived_Metrics!U5<=Inputs_Theory!$L$10,1,IF(Derived_Metrics!U5<Inputs_Theory!$L$11,(Inputs_Theory!$L$11-Derived_Metrics!U5)/(Inputs_Theory!$L$11-Inputs_Theory!$L$10),0)))))+0.2*(MAX(0,MIN(1,(Derived_Metrics!L5-Inputs_Theory!$L$12)/(Inputs_Theory!$L$13-Inputs_Theory!$L$12))))) -> 0.83104771 | F5: =IF(Derived_Metrics!V5=0,0,IF(Derived_Metrics!F5<=Inputs_Theory!$L$14,0,IF(Derived_Metrics!F5<Inputs_Theory!$L$15,(Derived_Metrics!F5-Inputs_Theory!$L$14)/(Inputs_Theory!$L$15-Inputs_Theory!$L$14),IF(Derived_Metrics!F5<=Inputs_Theory!$L$16,1,IF(Derived_Metrics!F5<Inputs_Theory!$L$17,(Inputs_Theory!$L$17-Derived_Metrics!F5)/(Inputs_Theory!$L$17-Inputs_Theory!$L$16),0))))) -> 1 | G5: =IF(Derived_Metrics!V5=0,0,0.5*(MAX(0,MIN(1,(Derived_Metrics!I5-Inputs_Theory!$L$18)/(Inputs_Theory!$L$19-Inputs_Theory!$L$18))))+0.5*(MAX(0,MIN(1,(Inputs_Theory!$L$21-Derived_Metrics!H5)/(Inputs_Theory!$L$21-Inputs_Theory!$L$20))))) -> 0.53111959 | H5: =IF(Derived_Metrics!V5=0,0,0.35*Derived_Metrics!V5+0.25*MIN(1,Derived_Metrics!P5/Derived_Metrics!$P$8)+0.25*(MAX(0,MIN(1,(Inputs_Theory!$L$23-Derived_Metrics!T5)/(Inputs_Theory!$L$23-Inputs_Theory!$L$22))))+0.15*(MAX(0,MIN(1,(Inputs_Theory!$L$25-Derived_Metrics!Q5)/(Inputs_Theory!$L$25-Inputs_Theory!$L$24))))) -> 0.88229167 | I5: =IF(Derived_Metrics!V5=0,0,0.5*(IF(Derived_Metrics!S5<=Inputs_Theory!$L$26,0,IF(Derived_Metrics!S5<Inputs_Theory!$L$27,(Derived_Metrics!S5-Inputs_Theory!$L$26)/(Inputs_Theory!$L$27-Inputs_Theory!$L$26),IF(Derived_Metrics!S5<=Inputs_Theory!$L$28,1,IF(Derived_Metrics!S5<Inputs_Theory!$L$29,(Inputs_Theory!$L$29-Derived_Metrics!S5)/(Inputs_Theory!$L$29-Inputs_Theory!$L$28),0)))))+0.3*(IF(B5=0.875,0.6,IF(B5=1.75,1,0.8)))+0.2*(MAX(0,MIN(1,(Derived_Metrics!R5-Inputs_Theory!$L$30)/(Inputs_Theory!$L$31-Inputs_Theory!$L$30))))) -> 0.44944444 | J5: =IF(Derived_Metrics!V5=0,0,0.3*E5+0.2*F5+0.2*G5+0.15*H5+0.15*I5) -> 0.75529865 | K5: =IF(Derived_Metrics!V5=0,0,0.4*E5+0.25*F5+0.2*G5+0.05*H5+0.1*I5) -> 0.77770203 | L5: =IF(Derived_Metrics!V5=0,0,0.2*E5+0.1*F5+0.15*G5+0.3*H5+0.25*I5) -> 0.72292609 | M5: =_xlfn.RANK.EQ(J5,$J$4:$J$12,0) -> 6 | N5: =_xlfn.SINGLE(_xlfn.RANK.EQ(L5,$L$4:$L$12,0)) -> 7 | O5: THIN-WALL EXTREME | P5: Retain as the medium-height thin-wall control.
A6: =Derived_Metrics!A6 -> 3 | B6: =Derived_Metrics!B6 -> 0.875 | C6: =Derived_Metrics!C6 -> 5.25 | D6: =Derived_Metrics!D6 -> Solved | E6: =IF(Derived_Metrics!V6=0,0,0.45*(IF(Derived_Metrics!T6<=Inputs_Theory!$L$4,0,IF(Derived_Metrics!T6<Inputs_Theory!$L$5,(Derived_Metrics!T6-Inputs_Theory!$L$4)/(Inputs_Theory!$L$5-Inputs_Theory!$L$4),IF(Derived_Metrics!T6<=Inputs_Theory!$L$6,1,IF(Derived_Metrics!T6<Inputs_Theory!$L$7,(Inputs_Theory!$L$7-Derived_Metrics!T6)/(Inputs_Theory!$L$7-Inputs_Theory!$L$6),0)))))+0.35*(IF(Derived_Metrics!U6<=Inputs_Theory!$L$8,0,IF(Derived_Metrics!U6<Inputs_Theory!$L$9,(Derived_Metrics!U6-Inputs_Theory!$L$8)/(Inputs_Theory!$L$9-Inputs_Theory!$L$8),IF(Derived_Metrics!U6<=Inputs_Theory!$L$10,1,IF(Derived_Metrics!U6<Inputs_Theory!$L$11,(Inputs_Theory!$L$11-Derived_Metrics!U6)/(Inputs_Theory!$L$11-Inputs_Theory!$L$10),0)))))+0.2*(MAX(0,MIN(1,(Derived_Metrics!L6-Inputs_Theory!$L$12)/(Inputs_Theory!$L$13-Inputs_Theory!$L$12))))) -> 0.81580667 | F6: =IF(Derived_Metrics!V6=0,0,IF(Derived_Metrics!F6<=Inputs_Theory!$L$14,0,IF(Derived_Metrics!F6<Inputs_Theory!$L$15,(Derived_Metrics!F6-Inputs_Theory!$L$14)/(Inputs_Theory!$L$15-Inputs_Theory!$L$14),IF(Derived_Metrics!F6<=Inputs_Theory!$L$16,1,IF(Derived_Metrics!F6<Inputs_Theory!$L$17,(Inputs_Theory!$L$17-Derived_Metrics!F6)/(Inputs_Theory!$L$17-Inputs_Theory!$L$16),0))))) -> 0.54826667 | G6: =IF(Derived_Metrics!V6=0,0,0.5*(MAX(0,MIN(1,(Derived_Metrics!I6-Inputs_Theory!$L$18)/(Inputs_Theory!$L$19-Inputs_Theory!$L$18))))+0.5*(MAX(0,MIN(1,(Inputs_Theory!$L$21-Derived_Metrics!H6)/(Inputs_Theory!$L$21-Inputs_Theory!$L$20))))) -> 0.62389648 | H6: =IF(Derived_Metrics!V6=0,0,0.35*Derived_Metrics!V6+0.25*MIN(1,Derived_Metrics!P6/Derived_Metrics!$P$8)+0.25*(MAX(0,MIN(1,(Inputs_Theory!$L$23-Derived_Metrics!T6)/(Inputs_Theory!$L$23-Inputs_Theory!$L$22))))+0.15*(MAX(0,MIN(1,(Inputs_Theory!$L$25-Derived_Metrics!Q6)/(Inputs_Theory!$L$25-Inputs_Theory!$L$24))))) -> 0.65401235 | I6: =IF(Derived_Metrics!V6=0,0,0.5*(IF(Derived_Metrics!S6<=Inputs_Theory!$L$26,0,IF(Derived_Metrics!S6<Inputs_Theory!$L$27,(Derived_Metrics!S6-Inputs_Theory!$L$26)/(Inputs_Theory!$L$27-Inputs_Theory!$L$26),IF(Derived_Metrics!S6<=Inputs_Theory!$L$28,1,IF(Derived_Metrics!S6<Inputs_Theory!$L$29,(Inputs_Theory!$L$29-Derived_Metrics!S6)/(Inputs_Theory!$L$29-Inputs_Theory!$L$28),0)))))+0.3*(IF(B6=0.875,0.6,IF(B6=1.75,1,0.8)))+0.2*(MAX(0,MIN(1,(Derived_Metrics!R6-Inputs_Theory!$L$30)/(Inputs_Theory!$L$31-Inputs_Theory!$L$30))))) -> 0.44944444 | J6: =IF(Derived_Metrics!V6=0,0,0.3*E6+0.2*F6+0.2*G6+0.15*H6+0.15*I6) -> 0.64469315 | K6: =IF(Derived_Metrics!V6=0,0,0.4*E6+0.25*F6+0.2*G6+0.05*H6+0.1*I6) -> 0.66581369 | L6: =IF(Derived_Metrics!V6=0,0,0.2*E6+0.1*F6+0.15*G6+0.3*H6+0.25*I6) -> 0.62013729 | M6: 8 | N6: =_xlfn.SINGLE(_xlfn.RANK.EQ(L6,$L$4:$L$12,0)) -> 8 | O6: THIN-WALL EXTREME | P6: Retain as the tall thin-wall control; inspect folding and fatigue.
A7: =Derived_Metrics!A7 -> 4 | B7: =Derived_Metrics!B7 -> 1.75 | C7: =Derived_Metrics!C7 -> 1.75 | D7: =Derived_Metrics!D7 -> Solved | E7: =IF(Derived_Metrics!V7=0,0,0.45*(IF(Derived_Metrics!T7<=Inputs_Theory!$L$4,0,IF(Derived_Metrics!T7<Inputs_Theory!$L$5,(Derived_Metrics!T7-Inputs_Theory!$L$4)/(Inputs_Theory!$L$5-Inputs_Theory!$L$4),IF(Derived_Metrics!T7<=Inputs_Theory!$L$6,1,IF(Derived_Metrics!T7<Inputs_Theory!$L$7,(Inputs_Theory!$L$7-Derived_Metrics!T7)/(Inputs_Theory!$L$7-Inputs_Theory!$L$6),0)))))+0.35*(IF(Derived_Metrics!U7<=Inputs_Theory!$L$8,0,IF(Derived_Metrics!U7<Inputs_Theory!$L$9,(Derived_Metrics!U7-Inputs_Theory!$L$8)/(Inputs_Theory!$L$9-Inputs_Theory!$L$8),IF(Derived_Metrics!U7<=Inputs_Theory!$L$10,1,IF(Derived_Metrics!U7<Inputs_Theory!$L$11,(Inputs_Theory!$L$11-Derived_Metrics!U7)/(Inputs_Theory!$L$11-Inputs_Theory!$L$10),0)))))+0.2*(MAX(0,MIN(1,(Derived_Metrics!L7-Inputs_Theory!$L$12)/(Inputs_Theory!$L$13-Inputs_Theory!$L$12))))) -> 0.6759087 | F7: =IF(Derived_Metrics!V7=0,0,IF(Derived_Metrics!F7<=Inputs_Theory!$L$14,0,IF(Derived_Metrics!F7<Inputs_Theory!$L$15,(Derived_Metrics!F7-Inputs_Theory!$L$14)/(Inputs_Theory!$L$15-Inputs_Theory!$L$14),IF(Derived_Metrics!F7<=Inputs_Theory!$L$16,1,IF(Derived_Metrics!F7<Inputs_Theory!$L$17,(Inputs_Theory!$L$17-Derived_Metrics!F7)/(Inputs_Theory!$L$17-Inputs_Theory!$L$16),0))))) -> 0.3816 | G7: =IF(Derived_Metrics!V7=0,0,0.5*(MAX(0,MIN(1,(Derived_Metrics!I7-Inputs_Theory!$L$18)/(Inputs_Theory!$L$19-Inputs_Theory!$L$18))))+0.5*(MAX(0,MIN(1,(Inputs_Theory!$L$21-Derived_Metrics!H7)/(Inputs_Theory!$L$21-Inputs_Theory!$L$20))))) -> 0.56743683 | H7: =IF(Derived_Metrics!V7=0,0,0.35*Derived_Metrics!V7+0.25*MIN(1,Derived_Metrics!P7/Derived_Metrics!$P$8)+0.25*(MAX(0,MIN(1,(Inputs_Theory!$L$23-Derived_Metrics!T7)/(Inputs_Theory!$L$23-Inputs_Theory!$L$22))))+0.15*(MAX(0,MIN(1,(Inputs_Theory!$L$25-Derived_Metrics!Q7)/(Inputs_Theory!$L$25-Inputs_Theory!$L$24))))) -> 1 | I7: =IF(Derived_Metrics!V7=0,0,0.5*(IF(Derived_Metrics!S7<=Inputs_Theory!$L$26,0,IF(Derived_Metrics!S7<Inputs_Theory!$L$27,(Derived_Metrics!S7-Inputs_Theory!$L$26)/(Inputs_Theory!$L$27-Inputs_Theory!$L$26),IF(Derived_Metrics!S7<=Inputs_Theory!$L$28,1,IF(Derived_Metrics!S7<Inputs_Theory!$L$29,(Inputs_Theory!$L$29-Derived_Metrics!S7)/(Inputs_Theory!$L$29-Inputs_Theory!$L$28),0)))))+0.3*(IF(B7=0.875,0.6,IF(B7=1.75,1,0.8)))+0.2*(MAX(0,MIN(1,(Derived_Metrics!R7-Inputs_Theory!$L$30)/(Inputs_Theory!$L$31-Inputs_Theory!$L$30))))) -> 1 | J7: =IF(Derived_Metrics!V7=0,0,0.3*E7+0.2*F7+0.2*G7+0.15*H7+0.15*I7) -> 0.69257997 | K7: =IF(Derived_Metrics!V7=0,0,0.4*E7+0.25*F7+0.2*G7+0.05*H7+0.1*I7) -> 0.62925084 | L7: =IF(Derived_Metrics!V7=0,0,0.2*E7+0.1*F7+0.15*G7+0.3*H7+0.25*I7) -> 0.80845726 | M7: =_xlfn.SINGLE(_xlfn.RANK.EQ(J7,$J$4:$J$12,0)) -> 7 | N7: =_xlfn.SINGLE(_xlfn.RANK.EQ(L7,$L$4:$L$12,0)) -> 3 | O7: SHORT / STIFF CONTROL | P7: Use as the durability and strong-activation control.
A8: =Derived_Metrics!A8 -> 5 | B8: =Derived_Metrics!B8 -> 1.75 | C8: =Derived_Metrics!C8 -> 3.5 | D8: =Derived_Metrics!D8 -> Solved | E8: =IF(Derived_Metrics!V8=0,0,0.45*(IF(Derived_Metrics!T8<=Inputs_Theory!$L$4,0,IF(Derived_Metrics!T8<Inputs_Theory!$L$5,(Derived_Metrics!T8-Inputs_Theory!$L$4)/(Inputs_Theory!$L$5-Inputs_Theory!$L$4),IF(Derived_Metrics!T8<=Inputs_Theory!$L$6,1,IF(Derived_Metrics!T8<Inputs_Theory!$L$7,(Inputs_Theory!$L$7-Derived_Metrics!T8)/(Inputs_Theory!$L$7-Inputs_Theory!$L$6),0)))))+0.35*(IF(Derived_Metrics!U8<=Inputs_Theory!$L$8,0,IF(Derived_Metrics!U8<Inputs_Theory!$L$9,(Derived_Metrics!U8-Inputs_Theory!$L$8)/(Inputs_Theory!$L$9-Inputs_Theory!$L$8),IF(Derived_Metrics!U8<=Inputs_Theory!$L$10,1,IF(Derived_Metrics!U8<Inputs_Theory!$L$11,(Inputs_Theory!$L$11-Derived_Metrics!U8)/(Inputs_Theory!$L$11-Inputs_Theory!$L$10),0)))))+0.2*(MAX(0,MIN(1,(Derived_Metrics!L8-Inputs_Theory!$L$12)/(Inputs_Theory!$L$13-Inputs_Theory!$L$12))))) -> 0.90994271 | F8: =IF(Derived_Metrics!V8=0,0,IF(Derived_Metrics!F8<=Inputs_Theory!$L$14,0,IF(Derived_Metrics!F8<Inputs_Theory!$L$15,(Derived_Metrics!F8-Inputs_Theory!$L$14)/(Inputs_Theory!$L$15-Inputs_Theory!$L$14),IF(Derived_Metrics!F8<=Inputs_Theory!$L$16,1,IF(Derived_Metrics!F8<Inputs_Theory!$L$17,(Inputs_Theory!$L$17-Derived_Metrics!F8)/(Inputs_Theory!$L$17-Inputs_Theory!$L$16),0))))) -> 1 | G8: =IF(Derived_Metrics!V8=0,0,0.5*(MAX(0,MIN(1,(Derived_Metrics!I8-Inputs_Theory!$L$18)/(Inputs_Theory!$L$19-Inputs_Theory!$L$18))))+0.5*(MAX(0,MIN(1,(Inputs_Theory!$L$21-Derived_Metrics!H8)/(Inputs_Theory!$L$21-Inputs_Theory!$L$20))))) -> 0.81537554 | H8: =IF(Derived_Metrics!V8=0,0,0.35*Derived_Metrics!V8+0.25*MIN(1,Derived_Metrics!P8/Derived_Metrics!$P$8)+0.25*(MAX(0,MIN(1,(Inputs_Theory!$L$23-Derived_Metrics!T8)/(Inputs_Theory!$L$23-Inputs_Theory!$L$22))))+0.15*(MAX(0,MIN(1,(Inputs_Theory!$L$25-Derived_Metrics!Q8)/(Inputs_Theory!$L$25-Inputs_Theory!$L$24))))) -> 1 | I8: =IF(Derived_Metrics!V8=0,0,0.5*(IF(Derived_Metrics!S8<=Inputs_Theory!$L$26,0,IF(Derived_Metrics!S8<Inputs_Theory!$L$27,(Derived_Metrics!S8-Inputs_Theory!$L$26)/(Inputs_Theory!$L$27-Inputs_Theory!$L$26),IF(Derived_Metrics!S8<=Inputs_Theory!$L$28,1,IF(Derived_Metrics!S8<Inputs_Theory!$L$29,(Inputs_Theory!$L$29-Derived_Metrics!S8)/(Inputs_Theory!$L$29-Inputs_Theory!$L$28),0)))))+0.3*(IF(B8=0.875,0.6,IF(B8=1.75,1,0.8)))+0.2*(MAX(0,MIN(1,(Derived_Metrics!R8-Inputs_Theory!$L$30)/(Inputs_Theory!$L$31-Inputs_Theory!$L$30))))) -> 1 | J8: =IF(Derived_Metrics!V8=0,0,0.3*E8+0.2*F8+0.2*G8+0.15*H8+0.15*I8) -> 0.93605792 | K8: =IF(Derived_Metrics!V8=0,0,0.4*E8+0.25*F8+0.2*G8+0.05*H8+0.1*I8) -> 0.92705219 | L8: =IF(Derived_Metrics!V8=0,0,0.2*E8+0.1*F8+0.15*G8+0.3*H8+0.25*I8) -> 0.95429487 | M8: =_xlfn.SINGLE(_xlfn.RANK.EQ(J8,$J$4:$J$12,0)) -> 2 | N8: =_xlfn.SINGLE(_xlfn.RANK.EQ(L8,$L$4:$L$12,0)) -> 1 | O8: PRIMARY CHALLENGER | P8: Best durability-oriented preferred-wall design; fabricate alongside Run 6.
A9: =Derived_Metrics!A9 -> 6 | B9: =Derived_Metrics!B9 -> 1.75 | C9: =Derived_Metrics!C9 -> 5.25 | D9: =Derived_Metrics!D9 -> Solved | E9: =IF(Derived_Metrics!V9=0,0,0.45*(IF(Derived_Metrics!T9<=Inputs_Theory!$L$4,0,IF(Derived_Metrics!T9<Inputs_Theory!$L$5,(Derived_Metrics!T9-Inputs_Theory!$L$4)/(Inputs_Theory!$L$5-Inputs_Theory!$L$4),IF(Derived_Metrics!T9<=Inputs_Theory!$L$6,1,IF(Derived_Metrics!T9<Inputs_Theory!$L$7,(Inputs_Theory!$L$7-Derived_Metrics!T9)/(Inputs_Theory!$L$7-Inputs_Theory!$L$6),0)))))+0.35*(IF(Derived_Metrics!U9<=Inputs_Theory!$L$8,0,IF(Derived_Metrics!U9<Inputs_Theory!$L$9,(Derived_Metrics!U9-Inputs_Theory!$L$8)/(Inputs_Theory!$L$9-Inputs_Theory!$L$8),IF(Derived_Metrics!U9<=Inputs_Theory!$L$10,1,IF(Derived_Metrics!U9<Inputs_Theory!$L$11,(Inputs_Theory!$L$11-Derived_Metrics!U9)/(Inputs_Theory!$L$11-Inputs_Theory!$L$10),0)))))+0.2*(MAX(0,MIN(1,(Derived_Metrics!L9-Inputs_Theory!$L$12)/(Inputs_Theory!$L$13-Inputs_Theory!$L$12))))) -> 1 | F9: =IF(Derived_Metrics!V9=0,0,IF(Derived_Metrics!F9<=Inputs_Theory!$L$14,0,IF(Derived_Metrics!F9<Inputs_Theory!$L$15,(Derived_Metrics!F9-Inputs_Theory!$L$14)/(Inputs_Theory!$L$15-Inputs_Theory!$L$14),IF(Derived_Metrics!F9<=Inputs_Theory!$L$16,1,IF(Derived_Metrics!F9<Inputs_Theory!$L$17,(Inputs_Theory!$L$17-Derived_Metrics!F9)/(Inputs_Theory!$L$17-Inputs_Theory!$L$16),0))))) -> 1 | G9: =IF(Derived_Metrics!V9=0,0,0.5*(MAX(0,MIN(1,(Derived_Metrics!I9-Inputs_Theory!$L$18)/(Inputs_Theory!$L$19-Inputs_Theory!$L$18))))+0.5*(MAX(0,MIN(1,(Inputs_Theory!$L$21-Derived_Metrics!H9)/(Inputs_Theory!$L$21-Inputs_Theory!$L$20))))) -> 0.94222857 | H9: =IF(Derived_Metrics!V9=0,0,0.35*Derived_Metrics!V9+0.25*MIN(1,Derived_Metrics!P9/Derived_Metrics!$P$8)+0.25*(MAX(0,MIN(1,(Inputs_Theory!$L$23-Derived_Metrics!T9)/(Inputs_Theory!$L$23-Inputs_Theory!$L$22))))+0.15*(MAX(0,MIN(1,(Inputs_Theory!$L$25-Derived_Metrics!Q9)/(Inputs_Theory!$L$25-Inputs_Theory!$L$24))))) -> 0.82407407 | I9: =IF(Derived_Metrics!V9=0,0,0.5*(IF(Derived_Metrics!S9<=Inputs_Theory!$L$26,0,IF(Derived_Metrics!S9<Inputs_Theory!$L$27,(Derived_Metrics!S9-Inputs_Theory!$L$26)/(Inputs_Theory!$L$27-Inputs_Theory!$L$26),IF(Derived_Metrics!S9<=Inputs_Theory!$L$28,1,IF(Derived_Metrics!S9<Inputs_Theory!$L$29,(Inputs_Theory!$L$29-Derived_Metrics!S9)/(Inputs_Theory!$L$29-Inputs_Theory!$L$28),0)))))+0.3*(IF(B9=0.875,0.6,IF(B9=1.75,1,0.8)))+0.2*(MAX(0,MIN(1,(Derived_Metrics!R9-Inputs_Theory!$L$30)/(Inputs_Theory!$L$31-Inputs_Theory!$L$30))))) -> 1 | J9: =IF(Derived_Metrics!V9=0,0,0.3*E9+0.2*F9+0.2*G9+0.15*H9+0.15*I9) -> 0.96205683 | K9: =IF(Derived_Metrics!V9=0,0,0.4*E9+0.25*F9+0.2*G9+0.05*H9+0.1*I9) -> 0.97964942 | L9: =IF(Derived_Metrics!V9=0,0,0.2*E9+0.1*F9+0.15*G9+0.3*H9+0.25*I9) -> 0.93855651 | M9: =_xlfn.SINGLE(_xlfn.RANK.EQ(J9,$J$4:$J$12,0)) -> 1 | N9: =_xlfn.SINGLE(_xlfn.RANK.EQ(L9,$L$4:$L$12,0)) -> 2 | O9: PRIMARY SELECTION | P9: Best balanced and sensitivity-oriented preferred-wall design.
A10: =Derived_Metrics!A10 -> 7 | B10: =Derived_Metrics!B10 -> 2.625 | C10: =Derived_Metrics!C10 -> 1.75 | D10: =Derived_Metrics!D10 -> Failed | E10: =IF(Derived_Metrics!V10=0,0,0.45*(IF(Derived_Metrics!T10<=Inputs_Theory!$L$4,0,IF(Derived_Metrics!T10<Inputs_Theory!$L$5,(Derived_Metrics!T10-Inputs_Theory!$L$4)/(Inputs_Theory!$L$5-Inputs_Theory!$L$4),IF(Derived_Metrics!T10<=Inputs_Theory!$L$6,1,IF(Derived_Metrics!T10<Inputs_Theory!$L$7,(Inputs_Theory!$L$7-Derived_Metrics!T10)/(Inputs_Theory!$L$7-Inputs_Theory!$L$6),0)))))+0.35*(IF(Derived_Metrics!U10<=Inputs_Theory!$L$8,0,IF(Derived_Metrics!U10<Inputs_Theory!$L$9,(Derived_Metrics!U10-Inputs_Theory!$L$8)/(Inputs_Theory!$L$9-Inputs_Theory!$L$8),IF(Derived_Metrics!U10<=Inputs_Theory!$L$10,1,IF(Derived_Metrics!U10<Inputs_Theory!$L$11,(Inputs_Theory!$L$11-Derived_Metrics!U10)/(Inputs_Theory!$L$11-Inputs_Theory!$L$10),0)))))+0.2*(MAX(0,MIN(1,(Derived_Metrics!L10-Inputs_Theory!$L$12)/(Inputs_Theory!$L$13-Inputs_Theory!$L$12))))) -> 0 | F10: =IF(Derived_Metrics!V10=0,0,IF(Derived_Metrics!F10<=Inputs_Theory!$L$14,0,IF(Derived_Metrics!F10<Inputs_Theory!$L$15,(Derived_Metrics!F10-Inputs_Theory!$L$14)/(Inputs_Theory!$L$15-Inputs_Theory!$L$14),IF(Derived_Metrics!F10<=Inputs_Theory!$L$16,1,IF(Derived_Metrics!F10<Inputs_Theory!$L$17,(Inputs_Theory!$L$17-Derived_Metrics!F10)/(Inputs_Theory!$L$17-Inputs_Theory!$L$16),0))))) -> 0 | G10: =IF(Derived_Metrics!V10=0,0,0.5*(MAX(0,MIN(1,(Derived_Metrics!I10-Inputs_Theory!$L$18)/(Inputs_Theory!$L$19-Inputs_Theory!$L$18))))+0.5*(MAX(0,MIN(1,(Inputs_Theory!$L$21-Derived_Metrics!H10)/(Inputs_Theory!$L$21-Inputs_Theory!$L$20))))) -> 0 | H10: =IF(Derived_Metrics!V10=0,0,0.35*Derived_Metrics!V10+0.25*MIN(1,Derived_Metrics!P10/Derived_Metrics!$P$8)+0.25*(MAX(0,MIN(1,(Inputs_Theory!$L$23-Derived_Metrics!T10)/(Inputs_Theory!$L$23-Inputs_Theory!$L$22))))+0.15*(MAX(0,MIN(1,(Inputs_Theory!$L$25-Derived_Metrics!Q10)/(Inputs_Theory!$L$25-Inputs_Theory!$L$24))))) -> 0 | I10: =IF(Derived_Metrics!V10=0,0,0.5*(IF(Derived_Metrics!S10<=Inputs_Theory!$L$26,0,IF(Derived_Metrics!S10<Inputs_Theory!$L$27,(Derived_Metrics!S10-Inputs_Theory!$L$26)/(Inputs_Theory!$L$27-Inputs_Theory!$L$26),IF(Derived_Metrics!S10<=Inputs_Theory!$L$28,1,IF(Derived_Metrics!S10<Inputs_Theory!$L$29,(Inputs_Theory!$L$29-Derived_Metrics!S10)/(Inputs_Theory!$L$29-Inputs_Theory!$L$28),0)))))+0.3*(IF(B10=0.875,0.6,IF(B10=1.75,1,0.8)))+0.2*(MAX(0,MIN(1,(Derived_Metrics!R10-Inputs_Theory!$L$30)/(Inputs_Theory!$L$31-Inputs_Theory!$L$30))))) -> 0 | J10: =IF(Derived_Metrics!V10=0,0,0.3*E10+0.2*F10+0.2*G10+0.15*H10+0.15*I10) -> 0 | K10: =IF(Derived_Metrics!V10=0,0,0.4*E10+0.25*F10+0.2*G10+0.05*H10+0.1*I10) -> 0 | L10: =IF(Derived_Metrics!V10=0,0,0.2*E10+0.1*F10+0.15*G10+0.3*H10+0.25*I10) -> 0 | M10: =_xlfn.SINGLE(_xlfn.RANK.EQ(J10,$J$4:$J$12,0)) -> 9 | N10: =_xlfn.SINGLE(_xlfn.RANK.EQ(L10,$L$4:$L$12,0)) -> 9 | O10: FAIL — TARGET DISPLACEMENT | P10: Reject from the primary design set; retain failed solution only as diagnostic evidence.
A11: =Derived_Metrics!A11 -> 8 | B11: =Derived_Metrics!B11 -> 2.625 | C11: =Derived_Metrics!C11 -> 3.5 | D11: =Derived_Metrics!D11 -> Solved | E11: =IF(Derived_Metrics!V11=0,0,0.45*(IF(Derived_Metrics!T11<=Inputs_Theory!$L$4,0,IF(Derived_Metrics!T11<Inputs_Theory!$L$5,(Derived_Metrics!T11-Inputs_Theory!$L$4)/(Inputs_Theory!$L$5-Inputs_Theory!$L$4),IF(Derived_Metrics!T11<=Inputs_Theory!$L$6,1,IF(Derived_Metrics!T11<Inputs_Theory!$L$7,(Inputs_Theory!$L$7-Derived_Metrics!T11)/(Inputs_Theory!$L$7-Inputs_Theory!$L$6),0)))))+0.35*(IF(Derived_Metrics!U11<=Inputs_Theory!$L$8,0,IF(Derived_Metrics!U11<Inputs_Theory!$L$9,(Derived_Metrics!U11-Inputs_Theory!$L$8)/(Inputs_Theory!$L$9-Inputs_Theory!$L$8),IF(Derived_Metrics!U11<=Inputs_Theory!$L$10,1,IF(Derived_Metrics!U11<Inputs_Theory!$L$11,(Inputs_Theory!$L$11-Derived_Metrics!U11)/(Inputs_Theory!$L$11-Inputs_Theory!$L$10),0)))))+0.2*(MAX(0,MIN(1,(Derived_Metrics!L11-Inputs_Theory!$L$12)/(Inputs_Theory!$L$13-Inputs_Theory!$L$12))))) -> 0.94849495 | F11: =IF(Derived_Metrics!V11=0,0,IF(Derived_Metrics!F11<=Inputs_Theory!$L$14,0,IF(Derived_Metrics!F11<Inputs_Theory!$L$15,(Derived_Metrics!F11-Inputs_Theory!$L$14)/(Inputs_Theory!$L$15-Inputs_Theory!$L$14),IF(Derived_Metrics!F11<=Inputs_Theory!$L$16,1,IF(Derived_Metrics!F11<Inputs_Theory!$L$17,(Inputs_Theory!$L$17-Derived_Metrics!F11)/(Inputs_Theory!$L$17-Inputs_Theory!$L$16),0))))) -> 0.79705143 | G11: =IF(Derived_Metrics!V11=0,0,0.5*(MAX(0,MIN(1,(Derived_Metrics!I11-Inputs_Theory!$L$18)/(Inputs_Theory!$L$19-Inputs_Theory!$L$18))))+0.5*(MAX(0,MIN(1,(Inputs_Theory!$L$21-Derived_Metrics!H11)/(Inputs_Theory!$L$21-Inputs_Theory!$L$20))))) -> 0.7680185 | H11: =IF(Derived_Metrics!V11=0,0,0.35*Derived_Metrics!V11+0.25*MIN(1,Derived_Metrics!P11/Derived_Metrics!$P$8)+0.25*(MAX(0,MIN(1,(Inputs_Theory!$L$23-Derived_Metrics!T11)/(Inputs_Theory!$L$23-Inputs_Theory!$L$22))))+0.15*(MAX(0,MIN(1,(Inputs_Theory!$L$25-Derived_Metrics!Q11)/(Inputs_Theory!$L$25-Inputs_Theory!$L$24))))) -> 1 | I11: =IF(Derived_Metrics!V11=0,0,0.5*(IF(Derived_Metrics!S11<=Inputs_Theory!$L$26,0,IF(Derived_Metrics!S11<Inputs_Theory!$L$27,(Derived_Metrics!S11-Inputs_Theory!$L$26)/(Inputs_Theory!$L$27-Inputs_Theory!$L$26),IF(Derived_Metrics!S11<=Inputs_Theory!$L$28,1,IF(Derived_Metrics!S11<Inputs_Theory!$L$29,(Inputs_Theory!$L$29-Derived_Metrics!S11)/(Inputs_Theory!$L$29-Inputs_Theory!$L$28),0)))))+0.3*(IF(B11=0.875,0.6,IF(B11=1.75,1,0.8)))+0.2*(MAX(0,MIN(1,(Derived_Metrics!R11-Inputs_Theory!$L$30)/(Inputs_Theory!$L$31-Inputs_Theory!$L$30))))) -> 0.34807692 | J11: =IF(Derived_Metrics!V11=0,0,0.3*E11+0.2*F11+0.2*G11+0.15*H11+0.15*I11) -> 0.79977401 | K11: =IF(Derived_Metrics!V11=0,0,0.4*E11+0.25*F11+0.2*G11+0.05*H11+0.1*I11) -> 0.81707223 | L11: =IF(Derived_Metrics!V11=0,0,0.2*E11+0.1*F11+0.15*G11+0.3*H11+0.25*I11) -> 0.77162614 | M11: =_xlfn.SINGLE(_xlfn.RANK.EQ(J11,$J$4:$J$12,0)) -> 5 | N11: =_xlfn.SINGLE(_xlfn.RANK.EQ(L11,$L$4:$L$12,0)) -> 6 | O11: NEAR-SOLID CONTROL | P11: Strong response, but only 6.25% cavity area; use as a thick-wall control.
A12: =Derived_Metrics!A12 -> 9 | B12: =Derived_Metrics!B12 -> 2.625 | C12: =Derived_Metrics!C12 -> 5.25 | D12: =Derived_Metrics!D12 -> Solved | E12: =IF(Derived_Metrics!V12=0,0,0.45*(IF(Derived_Metrics!T12<=Inputs_Theory!$L$4,0,IF(Derived_Metrics!T12<Inputs_Theory!$L$5,(Derived_Metrics!T12-Inputs_Theory!$L$4)/(Inputs_Theory!$L$5-Inputs_Theory!$L$4),IF(Derived_Metrics!T12<=Inputs_Theory!$L$6,1,IF(Derived_Metrics!T12<Inputs_Theory!$L$7,(Inputs_Theory!$L$7-Derived_Metrics!T12)/(Inputs_Theory!$L$7-Inputs_Theory!$L$6),0)))))+0.35*(IF(Derived_Metrics!U12<=Inputs_Theory!$L$8,0,IF(Derived_Metrics!U12<Inputs_Theory!$L$9,(Derived_Metrics!U12-Inputs_Theory!$L$8)/(Inputs_Theory!$L$9-Inputs_Theory!$L$8),IF(Derived_Metrics!U12<=Inputs_Theory!$L$10,1,IF(Derived_Metrics!U12<Inputs_Theory!$L$11,(Inputs_Theory!$L$11-Derived_Metrics!U12)/(Inputs_Theory!$L$11-Inputs_Theory!$L$10),0)))))+0.2*(MAX(0,MIN(1,(Derived_Metrics!L12-Inputs_Theory!$L$12)/(Inputs_Theory!$L$13-Inputs_Theory!$L$12))))) -> 0.98110311 | F12: =IF(Derived_Metrics!V12=0,0,IF(Derived_Metrics!F12<=Inputs_Theory!$L$14,0,IF(Derived_Metrics!F12<Inputs_Theory!$L$15,(Derived_Metrics!F12-Inputs_Theory!$L$14)/(Inputs_Theory!$L$15-Inputs_Theory!$L$14),IF(Derived_Metrics!F12<=Inputs_Theory!$L$16,1,IF(Derived_Metrics!F12<Inputs_Theory!$L$17,(Inputs_Theory!$L$17-Derived_Metrics!F12)/(Inputs_Theory!$L$17-Inputs_Theory!$L$16),0))))) -> 1 | G12: =IF(Derived_Metrics!V12=0,0,0.5*(MAX(0,MIN(1,(Derived_Metrics!I12-Inputs_Theory!$L$18)/(Inputs_Theory!$L$19-Inputs_Theory!$L$18))))+0.5*(MAX(0,MIN(1,(Inputs_Theory!$L$21-Derived_Metrics!H12)/(Inputs_Theory!$L$21-Inputs_Theory!$L$20))))) -> 0.95673326 | H12: =IF(Derived_Metrics!V12=0,0,0.35*Derived_Metrics!V12+0.25*MIN(1,Derived_Metrics!P12/Derived_Metrics!$P$8)+0.25*(MAX(0,MIN(1,(Inputs_Theory!$L$23-Derived_Metrics!T12)/(Inputs_Theory!$L$23-Inputs_Theory!$L$22))))+0.15*(MAX(0,MIN(1,(Inputs_Theory!$L$25-Derived_Metrics!Q12)/(Inputs_Theory!$L$25-Inputs_Theory!$L$24))))) -> 0.8287037 | I12: =IF(Derived_Metrics!V12=0,0,0.5*(IF(Derived_Metrics!S12<=Inputs_Theory!$L$26,0,IF(Derived_Metrics!S12<Inputs_Theory!$L$27,(Derived_Metrics!S12-Inputs_Theory!$L$26)/(Inputs_Theory!$L$27-Inputs_Theory!$L$26),IF(Derived_Metrics!S12<=Inputs_Theory!$L$28,1,IF(Derived_Metrics!S12<Inputs_Theory!$L$29,(Inputs_Theory!$L$29-Derived_Metrics!S12)/(Inputs_Theory!$L$29-Inputs_Theory!$L$28),0)))))+0.3*(IF(B12=0.875,0.6,IF(B12=1.75,1,0.8)))+0.2*(MAX(0,MIN(1,(Derived_Metrics!R12-Inputs_Theory!$L$30)/(Inputs_Theory!$L$31-Inputs_Theory!$L$30))))) -> 0.34807692 | J12: =IF(Derived_Metrics!V12=0,0,0.3*E12+0.2*F12+0.2*G12+0.15*H12+0.15*I12) -> 0.86219468 | K12: =IF(Derived_Metrics!V12=0,0,0.4*E12+0.25*F12+0.2*G12+0.05*H12+0.1*I12) -> 0.91003077 | L12: =IF(Derived_Metrics!V12=0,0,0.2*E12+0.1*F12+0.15*G12+0.3*H12+0.25*I12) -> 0.77536095 | M12: =_xlfn.SINGLE(_xlfn.RANK.EQ(J12,$J$4:$J$12,0)) -> 3 | N12: =_xlfn.SINGLE(_xlfn.RANK.EQ(L12,$L$4:$L$12,0)) -> 5 | O12: NEAR-SOLID TALL CONTROL | P12: Useful to test whether the hollow mechanism adds value.

Sheet Factor_Effects
A1: Main Effects of Wall Thickness and Rod Height
A3: Factor | B3: Level (mm) | C3: Solved count | D3: Failed count | E3: Mean |Fz| (N) | F3: Mean secant k | G3: Mean eq. strain max | H3: Mean energy (mJ) | I3: Mean lateral ratio | J3: Mean localization | K3: Mean balanced score
A4: Wall thickness | B4: 0.875 | C4: =COUNTIFS(Derived_Metrics!$B$4:$B$12,B4,Derived_Metrics!$D$4:$D$12,"Solved") -> 3 | D4: =COUNTIFS(Derived_Metrics!$B$4:$B$12,B4,Derived_Metrics!$D$4:$D$12,"Failed") -> 0 | E4: =IF(C4=0,0,SUMIFS(Derived_Metrics!$E$4:$E$12,Derived_Metrics!$B$4:$B$12,B4,Derived_Metrics!$D$4:$D$12,"Solved")/C4) -> 0.27656333 | F4: =IF(C4=0,0,SUMIFS(Derived_Metrics!$F$4:$F$12,Derived_Metrics!$B$4:$B$12,B4,Derived_Metrics!$D$4:$D$12,"Solved")/C4) -> 0.22125067 | G4: =IF(C4=0,0,SUMIFS(Derived_Metrics!$T$4:$T$12,Derived_Metrics!$B$4:$B$12,B4,Derived_Metrics!$D$4:$D$12,"Solved")/C4) -> 0.37853 | H4: =IF(C4=0,0,SUMIFS(Derived_Metrics!$U$4:$U$12,Derived_Metrics!$B$4:$B$12,B4,Derived_Metrics!$D$4:$D$12,"Solved")/C4) -> 0.14938667 | I4: =IF(C4=0,0,SUMIFS(Derived_Metrics!$H$4:$H$12,Derived_Metrics!$B$4:$B$12,B4,Derived_Metrics!$D$4:$D$12,"Solved")/C4) -> 0.2423774 | J4: =IF(C4=0,0,SUMIFS(Derived_Metrics!$I$4:$I$12,Derived_Metrics!$B$4:$B$12,B4,Derived_Metrics!$D$4:$D$12,"Solved")/C4) -> 4.7139163 | K4: =IF(C4=0,0,SUMIFS(Combined_Ranking!$J$4:$J$12,Combined_Ranking!$B$4:$B$12,B4,Combined_Ranking!$D$4:$D$12,"Solved")/C4) -> 0.73989395
A5: Wall thickness | B5: 1.75 | C5: =COUNTIFS(Derived_Metrics!$B$4:$B$12,B5,Derived_Metrics!$D$4:$D$12,"Solved") -> 3 | D5: =COUNTIFS(Derived_Metrics!$B$4:$B$12,B5,Derived_Metrics!$D$4:$D$12,"Failed") -> 0 | E5: =IF(C5=0,0,SUMIFS(Derived_Metrics!$E$4:$E$12,Derived_Metrics!$B$4:$B$12,B5,Derived_Metrics!$D$4:$D$12,"Solved")/C5) -> 0.69457 | F5: =IF(C5=0,0,SUMIFS(Derived_Metrics!$F$4:$F$12,Derived_Metrics!$B$4:$B$12,B5,Derived_Metrics!$D$4:$D$12,"Solved")/C5) -> 0.555656 | G5: =IF(C5=0,0,SUMIFS(Derived_Metrics!$T$4:$T$12,Derived_Metrics!$B$4:$B$12,B5,Derived_Metrics!$D$4:$D$12,"Solved")/C5) -> 0.44881 | H5: =IF(C5=0,0,SUMIFS(Derived_Metrics!$U$4:$U$12,Derived_Metrics!$B$4:$B$12,B5,Derived_Metrics!$D$4:$D$12,"Solved")/C5) -> 0.36127 | I5: =IF(C5=0,0,SUMIFS(Derived_Metrics!$H$4:$H$12,Derived_Metrics!$B$4:$B$12,B5,Derived_Metrics!$D$4:$D$12,"Solved")/C5) -> 0.29921638 | J5: =IF(C5=0,0,SUMIFS(Derived_Metrics!$I$4:$I$12,Derived_Metrics!$B$4:$B$12,B5,Derived_Metrics!$D$4:$D$12,"Solved")/C5) -> 8.741005 | K5: =IF(C5=0,0,SUMIFS(Combined_Ranking!$J$4:$J$12,Combined_Ranking!$B$4:$B$12,B5,Combined_Ranking!$D$4:$D$12,"Solved")/C5) -> 0.86356491
